[2024-05-23T22:34:34.590+0000] {local_task_job_runner.py:120} INFO - ::group::Pre task execution logs
[2024-05-23T22:34:34.644+0000] {taskinstance.py:2076} INFO - Dependencies all met for dep_context=non-requeueable deps ti=<TaskInstance: our_first_dag.first_task manual__2024-05-23T22:34:33.966555+00:00 [queued]>
[2024-05-23T22:34:34.658+0000] {taskinstance.py:2076} INFO - Dependencies all met for dep_context=requeueable deps ti=<TaskInstance: our_first_dag.first_task manual__2024-05-23T22:34:33.966555+00:00 [queued]>
[2024-05-23T22:34:34.659+0000] {taskinstance.py:2306} INFO - Starting attempt 1 of 6
[2024-05-23T22:34:34.690+0000] {taskinstance.py:2330} INFO - Executing <Task(BashOperator): first_task> on 2024-05-23 22:34:33.966555+00:00
[2024-05-23T22:34:34.704+0000] {standard_task_runner.py:90} INFO - Running: ['***', 'tasks', 'run', 'our_first_dag', 'first_task', 'manual__2024-05-23T22:34:33.966555+00:00', '--job-id', '3', '--raw', '--subdir', 'DAGS_FOLDER/our_first_dag.py', '--cfg-path', '/tmp/tmpom8zpc3g']
[2024-05-23T22:34:34.715+0000] {standard_task_runner.py:91} INFO - Job 3: Subtask first_task
[2024-05-23T22:34:34.718+0000] {logging_mixin.py:188} WARNING - /home/***/.local/lib/python3.12/site-packages/***/task/task_runner/standard_task_runner.py:61 DeprecationWarning: This process (pid=3050) is multi-threaded, use of fork() may lead to deadlocks in the child.
[2024-05-23T22:34:34.722+0000] {standard_task_runner.py:63} INFO - Started process 3051 to run task
[2024-05-23T22:34:34.838+0000] {task_command.py:426} INFO - Running <TaskInstance: our_first_dag.first_task manual__2024-05-23T22:34:33.966555+00:00 [running]> on host f2da7c0581b5
[2024-05-23T22:34:35.069+0000] {taskinstance.py:2648} INFO - Exporting env vars: AIRFLOW_CTX_DAG_OWNER='coder2j' AIRFLOW_CTX_DAG_ID='our_first_dag' AIRFLOW_CTX_TASK_ID='first_task' AIRFLOW_CTX_EXECUTION_DATE='2024-05-23T22:34:33.966555+00:00' AIRFLOW_CTX_TRY_NUMBER='1' AIRFLOW_CTX_DAG_RUN_ID='manual__2024-05-23T22:34:33.966555+00:00'
[2024-05-23T22:34:35.071+0000] {taskinstance.py:430} INFO - ::endgroup::
[2024-05-23T22:34:35.132+0000] {subprocess.py:63} INFO - Tmp dir root location: /tmp
[2024-05-23T22:34:35.134+0000] {subprocess.py:75} INFO - Running command: ['/usr/bin/bash', '-c', 'Hey, this is the first task']
[2024-05-23T22:34:35.152+0000] {subprocess.py:86} INFO - Output:
[2024-05-23T22:34:35.156+0000] {subprocess.py:93} INFO - /usr/bin/bash: line 1: Hey,: command not found
[2024-05-23T22:34:35.157+0000] {subprocess.py:97} INFO - Command exited with return code 127
[2024-05-23T22:34:35.159+0000] {taskinstance.py:441} INFO - ::group::Post task execution logs
[2024-05-23T22:34:35.179+0000] {taskinstance.py:2905} ERROR - Task failed with exception
Traceback (most recent call last):
  File "/home/airflow/.local/lib/python3.12/site-packages/airflow/models/taskinstance.py", line 465, in _execute_task
    result = _execute_callable(context=context, **execute_callable_kwargs)
             ^^^^^^^^^^^^^^^^^^^^^^^^^^^^^^^^^^^^^^^^^^^^^^^^^^^^^^^^^^^^^
  File "/home/airflow/.local/lib/python3.12/site-packages/airflow/models/taskinstance.py", line 432, in _execute_callable
    return execute_callable(context=context, **execute_callable_kwargs)
           ^^^^^^^^^^^^^^^^^^^^^^^^^^^^^^^^^^^^^^^^^^^^^^^^^^^^^^^^^^^^
  File "/home/airflow/.local/lib/python3.12/site-packages/airflow/models/baseoperator.py", line 400, in wrapper
    return func(self, *args, **kwargs)
           ^^^^^^^^^^^^^^^^^^^^^^^^^^^
  File "/home/airflow/.local/lib/python3.12/site-packages/airflow/operators/bash.py", line 243, in execute
    raise AirflowException(
airflow.exceptions.AirflowException: Bash command failed. The command returned a non-zero exit code 127.
[2024-05-23T22:34:35.188+0000] {taskinstance.py:1206} INFO - Marking task as UP_FOR_RETRY. dag_id=our_first_dag, task_id=first_task, run_id=manual__2024-05-23T22:34:33.966555+00:00, execution_date=20240523T223433, start_date=20240523T223434, end_date=20240523T223435
[2024-05-23T22:34:35.207+0000] {standard_task_runner.py:110} ERROR - Failed to execute job 3 for task first_task (Bash command failed. The command returned a non-zero exit code 127.; 3051)
[2024-05-23T22:34:35.233+0000] {local_task_job_runner.py:240} INFO - Task exited with return code 1
[2024-05-23T22:34:35.262+0000] {taskinstance.py:3498} INFO - 0 downstream tasks scheduled from follow-on schedule check
[2024-05-23T22:34:35.265+0000] {local_task_job_runner.py:222} INFO - ::endgroup::
