[2024-05-23T22:36:36.254+0000] {local_task_job_runner.py:120} INFO - ::group::Pre task execution logs
[2024-05-23T22:36:36.301+0000] {taskinstance.py:2076} INFO - Dependencies all met for dep_context=non-requeueable deps ti=<TaskInstance: our_first_dag.first_task manual__2024-05-23T22:34:33.966555+00:00 [queued]>
[2024-05-23T22:36:36.314+0000] {taskinstance.py:2076} INFO - Dependencies all met for dep_context=requeueable deps ti=<TaskInstance: our_first_dag.first_task manual__2024-05-23T22:34:33.966555+00:00 [queued]>
[2024-05-23T22:36:36.315+0000] {taskinstance.py:2306} INFO - Starting attempt 2 of 6
[2024-05-23T22:36:36.334+0000] {taskinstance.py:2330} INFO - Executing <Task(BashOperator): first_task> on 2024-05-23 22:34:33.966555+00:00
[2024-05-23T22:36:36.342+0000] {standard_task_runner.py:90} INFO - Running: ['***', 'tasks', 'run', 'our_first_dag', 'first_task', 'manual__2024-05-23T22:34:33.966555+00:00', '--job-id', '4', '--raw', '--subdir', 'DAGS_FOLDER/our_first_dag.py', '--cfg-path', '/tmp/tmpftujq2zm']
[2024-05-23T22:36:36.346+0000] {standard_task_runner.py:91} INFO - Job 4: Subtask first_task
[2024-05-23T22:36:36.348+0000] {logging_mixin.py:188} WARNING - /home/***/.local/lib/python3.12/site-packages/***/task/task_runner/standard_task_runner.py:61 DeprecationWarning: This process (pid=3097) is multi-threaded, use of fork() may lead to deadlocks in the child.
[2024-05-23T22:36:36.349+0000] {standard_task_runner.py:63} INFO - Started process 3098 to run task
[2024-05-23T22:36:36.410+0000] {task_command.py:426} INFO - Running <TaskInstance: our_first_dag.first_task manual__2024-05-23T22:34:33.966555+00:00 [running]> on host f2da7c0581b5
[2024-05-23T22:36:36.526+0000] {taskinstance.py:2648} INFO - Exporting env vars: AIRFLOW_CTX_DAG_OWNER='coder2j' AIRFLOW_CTX_DAG_ID='our_first_dag' AIRFLOW_CTX_TASK_ID='first_task' AIRFLOW_CTX_EXECUTION_DATE='2024-05-23T22:34:33.966555+00:00' AIRFLOW_CTX_TRY_NUMBER='2' AIRFLOW_CTX_DAG_RUN_ID='manual__2024-05-23T22:34:33.966555+00:00'
[2024-05-23T22:36:36.528+0000] {taskinstance.py:430} INFO - ::endgroup::
[2024-05-23T22:36:36.551+0000] {subprocess.py:63} INFO - Tmp dir root location: /tmp
[2024-05-23T22:36:36.552+0000] {subprocess.py:75} INFO - Running command: ['/usr/bin/bash', '-c', 'Hey, this is the first task']
[2024-05-23T22:36:36.562+0000] {subprocess.py:86} INFO - Output:
[2024-05-23T22:36:36.565+0000] {subprocess.py:93} INFO - /usr/bin/bash: line 1: Hey,: command not found
[2024-05-23T22:36:36.566+0000] {subprocess.py:97} INFO - Command exited with return code 127
[2024-05-23T22:36:36.567+0000] {taskinstance.py:441} INFO - ::group::Post task execution logs
[2024-05-23T22:36:36.581+0000] {taskinstance.py:2905} ERROR - Task failed with exception
Traceback (most recent call last):
  File "/home/airflow/.local/lib/python3.12/site-packages/airflow/models/taskinstance.py", line 465, in _execute_task
    result = _execute_callable(context=context, **execute_callable_kwargs)
             ^^^^^^^^^^^^^^^^^^^^^^^^^^^^^^^^^^^^^^^^^^^^^^^^^^^^^^^^^^^^^
  File "/home/airflow/.local/lib/python3.12/site-packages/airflow/models/taskinstance.py", line 432, in _execute_callable
    return execute_callable(context=context, **execute_callable_kwargs)
           ^^^^^^^^^^^^^^^^^^^^^^^^^^^^^^^^^^^^^^^^^^^^^^^^^^^^^^^^^^^^
  File "/home/airflow/.local/lib/python3.12/site-packages/airflow/models/baseoperator.py", line 400, in wrapper
    return func(self, *args, **kwargs)
           ^^^^^^^^^^^^^^^^^^^^^^^^^^^
  File "/home/airflow/.local/lib/python3.12/site-packages/airflow/operators/bash.py", line 243, in execute
    raise AirflowException(
airflow.exceptions.AirflowException: Bash command failed. The command returned a non-zero exit code 127.
[2024-05-23T22:36:36.588+0000] {taskinstance.py:1206} INFO - Marking task as UP_FOR_RETRY. dag_id=our_first_dag, task_id=first_task, run_id=manual__2024-05-23T22:34:33.966555+00:00, execution_date=20240523T223433, start_date=20240523T223636, end_date=20240523T223636
[2024-05-23T22:36:36.604+0000] {standard_task_runner.py:110} ERROR - Failed to execute job 4 for task first_task (Bash command failed. The command returned a non-zero exit code 127.; 3098)
[2024-05-23T22:36:36.615+0000] {local_task_job_runner.py:240} INFO - Task exited with return code 1
[2024-05-23T22:36:36.638+0000] {taskinstance.py:3498} INFO - 0 downstream tasks scheduled from follow-on schedule check
[2024-05-23T22:36:36.640+0000] {local_task_job_runner.py:222} INFO - ::endgroup::
